</span> - normal - INFO - [{"_class": "hudson.model.FreeStyleProject", "color": "notbuilt", "fullname": "task", "name": "task", "url": "http://localhost:8080/job/task/"}]
</span> - normal - INFO - {"_class": "hudson.model.FreeStyleProject", "actions": [{}, {}, {}, {"_class": "com.cloudbees.plugins.credentials.ViewCredentialsAction"}], "buildable": true, "builds": [], "color": "notbuilt", "concurrentBuild": false, "description": null, "displayName": "task", "displayNameOrNull": null, "downstreamProjects": [], "firstBuild": null, "fullDisplayName": "task", "fullName": "task", "healthReport": [], "inQueue": false, "keepDependencies": false, "labelExpression": null, "lastBuild": null, "lastCompletedBuild": null, "lastFailedBuild": null, "lastStableBuild": null, "lastSuccessfulBuild": null, "lastUnstableBuild": null, "lastUnsuccessfulBuild": null, "name": "task", "nextBuildNumber": 1, "property": [], "queueItem": null, "scm": {"_class": "hudson.scm.NullSCM"}, "upstreamProjects": [], "url": "http://localhost:8080/job/task/"}
</span> - normal - ERROR - job[tasks] does not exist
Traceback (most recent call last):
  File "C:\Users\EYOYAYO\AppData\Local\Programs\Python\Python36\lib\site-packages\jenkins\__init__.py", line 560, in jenkins_request
    self._request(req))
  File "C:\Users\EYOYAYO\AppData\Local\Programs\Python\Python36\lib\site-packages\jenkins\__init__.py", line 511, in _response_handler
    response.raise_for_status()
  File "C:\Users\EYOYAYO\AppData\Local\Programs\Python\Python36\lib\site-packages\requests\models.py", line 939, in raise_for_status
    raise HTTPError(http_error_msg, response=self)
requests.exceptions.HTTPError: 404 Client Error: Not Found for url: http://localhost:8080/job/tasks/api/json?depth=0

During handling of the above exception, another exception occurred:

Traceback (most recent call last):
  File "C:\Users\EYOYAYO\AppData\Local\Programs\Python\Python36\lib\site-packages\jenkins\__init__.py", line 445, in get_job_info
    'GET', self._build_url(JOB_INFO, locals())
  File "C:\Users\EYOYAYO\AppData\Local\Programs\Python\Python36\lib\site-packages\jenkins\__init__.py", line 541, in jenkins_open
    return self.jenkins_request(req, add_crumb, resolve_auth).text
  File "C:\Users\EYOYAYO\AppData\Local\Programs\Python\Python36\lib\site-packages\jenkins\__init__.py", line 573, in jenkins_request
    raise NotFoundException('Requested item could not be found')
jenkins.NotFoundException: Requested item could not be found

During handling of the above exception, another exception occurred:

Traceback (most recent call last):
  File "D:\Coding\Python\Tasks\venv\bin\Jobs.py", line 69, in get_task
    jobs = self.server.get_job_info(task_name)
  File "C:\Users\EYOYAYO\AppData\Local\Programs\Python\Python36\lib\site-packages\jenkins\__init__.py", line 455, in get_job_info
    raise JenkinsException('job[%s] does not exist' % name)
jenkins.JenkinsException: job[tasks] does not exist
</span> - normal - INFO - <Response 45 bytes [200 OK]>
</span> - normal - ERROR - job[tasks] does not exist
Traceback (most recent call last):
  File "C:\Users\EYOYAYO\AppData\Local\Programs\Python\Python36\lib\site-packages\jenkins\__init__.py", line 560, in jenkins_request
    self._request(req))
  File "C:\Users\EYOYAYO\AppData\Local\Programs\Python\Python36\lib\site-packages\jenkins\__init__.py", line 511, in _response_handler
    response.raise_for_status()
  File "C:\Users\EYOYAYO\AppData\Local\Programs\Python\Python36\lib\site-packages\requests\models.py", line 939, in raise_for_status
    raise HTTPError(http_error_msg, response=self)
requests.exceptions.HTTPError: 404 Client Error: Not Found for url: http://localhost:8080/job/tasks/api/json?depth=0

During handling of the above exception, another exception occurred:

Traceback (most recent call last):
  File "C:\Users\EYOYAYO\AppData\Local\Programs\Python\Python36\lib\site-packages\jenkins\__init__.py", line 445, in get_job_info
    'GET', self._build_url(JOB_INFO, locals())
  File "C:\Users\EYOYAYO\AppData\Local\Programs\Python\Python36\lib\site-packages\jenkins\__init__.py", line 541, in jenkins_open
    return self.jenkins_request(req, add_crumb, resolve_auth).text
  File "C:\Users\EYOYAYO\AppData\Local\Programs\Python\Python36\lib\site-packages\jenkins\__init__.py", line 573, in jenkins_request
    raise NotFoundException('Requested item could not be found')
jenkins.NotFoundException: Requested item could not be found

During handling of the above exception, another exception occurred:

Traceback (most recent call last):
  File "D:\Coding\Python\Tasks\venv\bin\Jobs.py", line 69, in get_task
    jobs = self.server.get_job_info(task_name)
  File "C:\Users\EYOYAYO\AppData\Local\Programs\Python\Python36\lib\site-packages\jenkins\__init__.py", line 455, in get_job_info
    raise JenkinsException('job[%s] does not exist' % name)
jenkins.JenkinsException: job[tasks] does not exist
</span> - normal - INFO - <Response 45 bytes [200 OK]>
</span> - normal - INFO - {"_class": "hudson.model.FreeStyleProject", "actions": [{}, {}, {}, {"_class": "com.cloudbees.plugins.credentials.ViewCredentialsAction"}], "buildable": true, "builds": [], "color": "notbuilt", "concurrentBuild": false, "description": null, "displayName": "task", "displayNameOrNull": null, "downstreamProjects": [], "firstBuild": null, "fullDisplayName": "task", "fullName": "task", "healthReport": [], "inQueue": false, "keepDependencies": false, "labelExpression": null, "lastBuild": null, "lastCompletedBuild": null, "lastFailedBuild": null, "lastStableBuild": null, "lastSuccessfulBuild": null, "lastUnstableBuild": null, "lastUnsuccessfulBuild": null, "name": "task", "nextBuildNumber": 1, "property": [], "queueItem": null, "scm": {"_class": "hudson.scm.NullSCM"}, "upstreamProjects": [], "url": "http://localhost:8080/job/task/"}
</span> - normal - INFO - [{"_class": "hudson.model.FreeStyleProject", "color": "notbuilt", "fullname": "task", "name": "task", "url": "http://localhost:8080/job/task/"}]
2018-08-12 21:00:02,947 - normal - INFO - {"_class": "hudson.model.FreeStyleProject", "actions": [{}, {}, {}, {"_class": "com.cloudbees.plugins.credentials.ViewCredentialsAction"}], "buildable": true, "builds": [], "color": "notbuilt", "concurrentBuild": false, "description": null, "displayName": "task", "displayNameOrNull": null, "downstreamProjects": [], "firstBuild": null, "fullDisplayName": "task", "fullName": "task", "healthReport": [], "inQueue": false, "keepDependencies": false, "labelExpression": null, "lastBuild": null, "lastCompletedBuild": null, "lastFailedBuild": null, "lastStableBuild": null, "lastSuccessfulBuild": null, "lastUnstableBuild": null, "lastUnsuccessfulBuild": null, "name": "task", "nextBuildNumber": 1, "property": [], "queueItem": null, "scm": {"_class": "hudson.scm.NullSCM"}, "upstreamProjects": [], "url": "http://localhost:8080/job/task/"}
2018-08-12 21:00:06,365 - normal - ERROR - job[tasks] does not exist
Traceback (most recent call last):
  File "C:\Users\EYOYAYO\AppData\Local\Programs\Python\Python36\lib\site-packages\jenkins\__init__.py", line 560, in jenkins_request
    self._request(req))
  File "C:\Users\EYOYAYO\AppData\Local\Programs\Python\Python36\lib\site-packages\jenkins\__init__.py", line 511, in _response_handler
    response.raise_for_status()
  File "C:\Users\EYOYAYO\AppData\Local\Programs\Python\Python36\lib\site-packages\requests\models.py", line 939, in raise_for_status
    raise HTTPError(http_error_msg, response=self)
requests.exceptions.HTTPError: 404 Client Error: Not Found for url: http://localhost:8080/job/tasks/api/json?depth=0

During handling of the above exception, another exception occurred:

Traceback (most recent call last):
  File "C:\Users\EYOYAYO\AppData\Local\Programs\Python\Python36\lib\site-packages\jenkins\__init__.py", line 445, in get_job_info
    'GET', self._build_url(JOB_INFO, locals())
  File "C:\Users\EYOYAYO\AppData\Local\Programs\Python\Python36\lib\site-packages\jenkins\__init__.py", line 541, in jenkins_open
    return self.jenkins_request(req, add_crumb, resolve_auth).text
  File "C:\Users\EYOYAYO\AppData\Local\Programs\Python\Python36\lib\site-packages\jenkins\__init__.py", line 573, in jenkins_request
    raise NotFoundException('Requested item could not be found')
jenkins.NotFoundException: Requested item could not be found

During handling of the above exception, another exception occurred:

Traceback (most recent call last):
  File "D:\Coding\Python\Tasks\venv\bin\Jobs.py", line 69, in get_task
    jobs = self.server.get_job_info(task_name)
  File "C:\Users\EYOYAYO\AppData\Local\Programs\Python\Python36\lib\site-packages\jenkins\__init__.py", line 455, in get_job_info
    raise JenkinsException('job[%s] does not exist' % name)
jenkins.JenkinsException: job[tasks] does not exist
2018-08-12 21:00:06,369 - normal - INFO - <Response 45 bytes [200 OK]>
2018-08-12 21:00:43,916 - normal - ERROR - job[tasks] does not exist
Traceback (most recent call last):
  File "C:\Users\EYOYAYO\AppData\Local\Programs\Python\Python36\lib\site-packages\jenkins\__init__.py", line 560, in jenkins_request
    self._request(req))
  File "C:\Users\EYOYAYO\AppData\Local\Programs\Python\Python36\lib\site-packages\jenkins\__init__.py", line 511, in _response_handler
    response.raise_for_status()
  File "C:\Users\EYOYAYO\AppData\Local\Programs\Python\Python36\lib\site-packages\requests\models.py", line 939, in raise_for_status
    raise HTTPError(http_error_msg, response=self)
requests.exceptions.HTTPError: 404 Client Error: Not Found for url: http://localhost:8080/job/tasks/api/json?depth=0

During handling of the above exception, another exception occurred:

Traceback (most recent call last):
  File "C:\Users\EYOYAYO\AppData\Local\Programs\Python\Python36\lib\site-packages\jenkins\__init__.py", line 445, in get_job_info
    'GET', self._build_url(JOB_INFO, locals())
  File "C:\Users\EYOYAYO\AppData\Local\Programs\Python\Python36\lib\site-packages\jenkins\__init__.py", line 541, in jenkins_open
    return self.jenkins_request(req, add_crumb, resolve_auth).text
  File "C:\Users\EYOYAYO\AppData\Local\Programs\Python\Python36\lib\site-packages\jenkins\__init__.py", line 573, in jenkins_request
    raise NotFoundException('Requested item could not be found')
jenkins.NotFoundException: Requested item could not be found

During handling of the above exception, another exception occurred:

Traceback (most recent call last):
  File "D:\Coding\Python\Tasks\venv\bin\Jobs.py", line 69, in get_task
    jobs = self.server.get_job_info(task_name)
  File "C:\Users\EYOYAYO\AppData\Local\Programs\Python\Python36\lib\site-packages\jenkins\__init__.py", line 455, in get_job_info
    raise JenkinsException('job[%s] does not exist' % name)
jenkins.JenkinsException: job[tasks] does not exist
2018-08-12 21:00:43,916 - normal - INFO - <Response 45 bytes [200 OK]>
2018-08-12 21:05:30,968 - normal - ERROR - job[tasks] does not exist
Traceback (most recent call last):
  File "C:\Users\EYOYAYO\AppData\Local\Programs\Python\Python36\lib\site-packages\jenkins\__init__.py", line 560, in jenkins_request
    self._request(req))
  File "C:\Users\EYOYAYO\AppData\Local\Programs\Python\Python36\lib\site-packages\jenkins\__init__.py", line 511, in _response_handler
    response.raise_for_status()
  File "C:\Users\EYOYAYO\AppData\Local\Programs\Python\Python36\lib\site-packages\requests\models.py", line 939, in raise_for_status
    raise HTTPError(http_error_msg, response=self)
requests.exceptions.HTTPError: 404 Client Error: Not Found for url: http://localhost:8080/job/tasks/api/json?depth=0

During handling of the above exception, another exception occurred:

Traceback (most recent call last):
  File "C:\Users\EYOYAYO\AppData\Local\Programs\Python\Python36\lib\site-packages\jenkins\__init__.py", line 445, in get_job_info
    'GET', self._build_url(JOB_INFO, locals())
  File "C:\Users\EYOYAYO\AppData\Local\Programs\Python\Python36\lib\site-packages\jenkins\__init__.py", line 541, in jenkins_open
    return self.jenkins_request(req, add_crumb, resolve_auth).text
  File "C:\Users\EYOYAYO\AppData\Local\Programs\Python\Python36\lib\site-packages\jenkins\__init__.py", line 573, in jenkins_request
    raise NotFoundException('Requested item could not be found')
jenkins.NotFoundException: Requested item could not be found

During handling of the above exception, another exception occurred:

Traceback (most recent call last):
  File "D:\Coding\Python\Tasks\venv\bin\Jobs.py", line 69, in get_task
    jobs = self.server.get_job_info(task_name)
  File "C:\Users\EYOYAYO\AppData\Local\Programs\Python\Python36\lib\site-packages\jenkins\__init__.py", line 455, in get_job_info
    raise JenkinsException('job[%s] does not exist' % name)
jenkins.JenkinsException: job[tasks] does not exist
2018-08-12 21:05:30,972 - normal - INFO - <Response 45 bytes [200 OK]>
2018-08-12 21:08:52,253 - normal - ERROR - job[tasks] does not exist
Traceback (most recent call last):
  File "C:\Users\EYOYAYO\AppData\Local\Programs\Python\Python36\lib\site-packages\jenkins\__init__.py", line 560, in jenkins_request
    self._request(req))
  File "C:\Users\EYOYAYO\AppData\Local\Programs\Python\Python36\lib\site-packages\jenkins\__init__.py", line 511, in _response_handler
    response.raise_for_status()
  File "C:\Users\EYOYAYO\AppData\Local\Programs\Python\Python36\lib\site-packages\requests\models.py", line 939, in raise_for_status
    raise HTTPError(http_error_msg, response=self)
requests.exceptions.HTTPError: 404 Client Error: Not Found for url: http://localhost:8080/job/tasks/api/json?depth=0

During handling of the above exception, another exception occurred:

Traceback (most recent call last):
  File "C:\Users\EYOYAYO\AppData\Local\Programs\Python\Python36\lib\site-packages\jenkins\__init__.py", line 445, in get_job_info
    'GET', self._build_url(JOB_INFO, locals())
  File "C:\Users\EYOYAYO\AppData\Local\Programs\Python\Python36\lib\site-packages\jenkins\__init__.py", line 541, in jenkins_open
    return self.jenkins_request(req, add_crumb, resolve_auth).text
  File "C:\Users\EYOYAYO\AppData\Local\Programs\Python\Python36\lib\site-packages\jenkins\__init__.py", line 573, in jenkins_request
    raise NotFoundException('Requested item could not be found')
jenkins.NotFoundException: Requested item could not be found

During handling of the above exception, another exception occurred:

Traceback (most recent call last):
  File "D:\Coding\Python\Tasks\venv\bin\Jobs.py", line 69, in get_task
    jobs = self.server.get_job_info(task_name)
  File "C:\Users\EYOYAYO\AppData\Local\Programs\Python\Python36\lib\site-packages\jenkins\__init__.py", line 455, in get_job_info
    raise JenkinsException('job[%s] does not exist' % name)
jenkins.JenkinsException: job[tasks] does not exist
2018-08-12 21:08:52,269 - normal - INFO - <Response 45 bytes [200 OK]>
2018-08-12 21:10:58,123 - normal - ERROR - job[tasks] does not exist
Traceback (most recent call last):
  File "C:\Users\EYOYAYO\AppData\Local\Programs\Python\Python36\lib\site-packages\jenkins\__init__.py", line 560, in jenkins_request
    self._request(req))
  File "C:\Users\EYOYAYO\AppData\Local\Programs\Python\Python36\lib\site-packages\jenkins\__init__.py", line 511, in _response_handler
    response.raise_for_status()
  File "C:\Users\EYOYAYO\AppData\Local\Programs\Python\Python36\lib\site-packages\requests\models.py", line 939, in raise_for_status
    raise HTTPError(http_error_msg, response=self)
requests.exceptions.HTTPError: 404 Client Error: Not Found for url: http://localhost:8080/job/tasks/api/json?depth=0

During handling of the above exception, another exception occurred:

Traceback (most recent call last):
  File "C:\Users\EYOYAYO\AppData\Local\Programs\Python\Python36\lib\site-packages\jenkins\__init__.py", line 445, in get_job_info
    'GET', self._build_url(JOB_INFO, locals())
  File "C:\Users\EYOYAYO\AppData\Local\Programs\Python\Python36\lib\site-packages\jenkins\__init__.py", line 541, in jenkins_open
    return self.jenkins_request(req, add_crumb, resolve_auth).text
  File "C:\Users\EYOYAYO\AppData\Local\Programs\Python\Python36\lib\site-packages\jenkins\__init__.py", line 573, in jenkins_request
    raise NotFoundException('Requested item could not be found')
jenkins.NotFoundException: Requested item could not be found

During handling of the above exception, another exception occurred:

Traceback (most recent call last):
  File "D:\Coding\Python\Tasks\venv\bin\Jobs.py", line 69, in get_task
    jobs = self.server.get_job_info(task_name)
  File "C:\Users\EYOYAYO\AppData\Local\Programs\Python\Python36\lib\site-packages\jenkins\__init__.py", line 455, in get_job_info
    raise JenkinsException('job[%s] does not exist' % name)
jenkins.JenkinsException: job[tasks] does not exist
2018-08-12 21:10:58,127 - normal - INFO - <Response 45 bytes [200 OK]>
2018-08-12 21:14:16,394 - normal - ERROR - job[tasks] does not exist
Traceback (most recent call last):
  File "C:\Users\EYOYAYO\AppData\Local\Programs\Python\Python36\lib\site-packages\jenkins\__init__.py", line 560, in jenkins_request
    self._request(req))
  File "C:\Users\EYOYAYO\AppData\Local\Programs\Python\Python36\lib\site-packages\jenkins\__init__.py", line 511, in _response_handler
    response.raise_for_status()
  File "C:\Users\EYOYAYO\AppData\Local\Programs\Python\Python36\lib\site-packages\requests\models.py", line 939, in raise_for_status
    raise HTTPError(http_error_msg, response=self)
requests.exceptions.HTTPError: 404 Client Error: Not Found for url: http://localhost:8080/job/tasks/api/json?depth=0

During handling of the above exception, another exception occurred:

Traceback (most recent call last):
  File "C:\Users\EYOYAYO\AppData\Local\Programs\Python\Python36\lib\site-packages\jenkins\__init__.py", line 445, in get_job_info
    'GET', self._build_url(JOB_INFO, locals())
  File "C:\Users\EYOYAYO\AppData\Local\Programs\Python\Python36\lib\site-packages\jenkins\__init__.py", line 541, in jenkins_open
    return self.jenkins_request(req, add_crumb, resolve_auth).text
  File "C:\Users\EYOYAYO\AppData\Local\Programs\Python\Python36\lib\site-packages\jenkins\__init__.py", line 573, in jenkins_request
    raise NotFoundException('Requested item could not be found')
jenkins.NotFoundException: Requested item could not be found

During handling of the above exception, another exception occurred:

Traceback (most recent call last):
  File "D:\Coding\Python\Tasks\venv\bin\Jobs.py", line 69, in get_task
    jobs = self.server.get_job_info(task_name)
  File "C:\Users\EYOYAYO\AppData\Local\Programs\Python\Python36\lib\site-packages\jenkins\__init__.py", line 455, in get_job_info
    raise JenkinsException('job[%s] does not exist' % name)
jenkins.JenkinsException: job[tasks] does not exist
2018-08-12 21:14:16,396 - normal - INFO - <Response 45 bytes [200 OK]>
2018-08-12 21:23:36,484 - normal - ERROR - Requested item could not be found
Traceback (most recent call last):
  File "C:\Users\EYOYAYO\AppData\Local\Programs\Python\Python36\lib\site-packages\jenkins\__init__.py", line 560, in jenkins_request
    self._request(req))
  File "C:\Users\EYOYAYO\AppData\Local\Programs\Python\Python36\lib\site-packages\jenkins\__init__.py", line 511, in _response_handler
    response.raise_for_status()
  File "C:\Users\EYOYAYO\AppData\Local\Programs\Python\Python36\lib\site-packages\requests\models.py", line 939, in raise_for_status
    raise HTTPError(http_error_msg, response=self)
requests.exceptions.HTTPError: 404 Client Error: Not Found for url: http://localhost:8080/job/tasks/build

During handling of the above exception, another exception occurred:

Traceback (most recent call last):
  File "D:\Coding\Python\Tasks\venv\bin\Jobs.py", line 99, in build_task
    jobs = self.server.build_job(task_name)
  File "C:\Users\EYOYAYO\AppData\Local\Programs\Python\Python36\lib\site-packages\jenkins\__init__.py", line 1276, in build_job
    'POST', self.build_job_url(name, parameters, token)))
  File "C:\Users\EYOYAYO\AppData\Local\Programs\Python\Python36\lib\site-packages\jenkins\__init__.py", line 573, in jenkins_request
    raise NotFoundException('Requested item could not be found')
jenkins.NotFoundException: Requested item could not be found
2018-08-12 21:23:36,486 - normal - INFO - <Response 81 bytes [200 OK]>
2018-08-12 21:23:47,789 - normal - ERROR - Requested item could not be found
Traceback (most recent call last):
  File "C:\Users\EYOYAYO\AppData\Local\Programs\Python\Python36\lib\site-packages\jenkins\__init__.py", line 560, in jenkins_request
    self._request(req))
  File "C:\Users\EYOYAYO\AppData\Local\Programs\Python\Python36\lib\site-packages\jenkins\__init__.py", line 511, in _response_handler
    response.raise_for_status()
  File "C:\Users\EYOYAYO\AppData\Local\Programs\Python\Python36\lib\site-packages\requests\models.py", line 939, in raise_for_status
    raise HTTPError(http_error_msg, response=self)
requests.exceptions.HTTPError: 404 Client Error: Not Found for url: http://localhost:8080/job/tasks/build

During handling of the above exception, another exception occurred:

Traceback (most recent call last):
  File "D:\Coding\Python\Tasks\venv\bin\Jobs.py", line 99, in build_task
    jobs = self.server.build_job(task_name)
  File "C:\Users\EYOYAYO\AppData\Local\Programs\Python\Python36\lib\site-packages\jenkins\__init__.py", line 1276, in build_job
    'POST', self.build_job_url(name, parameters, token)))
  File "C:\Users\EYOYAYO\AppData\Local\Programs\Python\Python36\lib\site-packages\jenkins\__init__.py", line 573, in jenkins_request
    raise NotFoundException('Requested item could not be found')
jenkins.NotFoundException: Requested item could not be found
2018-08-12 21:23:47,794 - normal - INFO - <Response 81 bytes [200 OK]>
2018-08-12 21:27:44,638 - normal - ERROR - Requested item could not be found
Traceback (most recent call last):
  File "C:\Users\EYOYAYO\AppData\Local\Programs\Python\Python36\lib\site-packages\jenkins\__init__.py", line 560, in jenkins_request
    self._request(req))
  File "C:\Users\EYOYAYO\AppData\Local\Programs\Python\Python36\lib\site-packages\jenkins\__init__.py", line 511, in _response_handler
    response.raise_for_status()
  File "C:\Users\EYOYAYO\AppData\Local\Programs\Python\Python36\lib\site-packages\requests\models.py", line 939, in raise_for_status
    raise HTTPError(http_error_msg, response=self)
requests.exceptions.HTTPError: 404 Client Error: Not Found for url: http://localhost:8080/job/tasks/enable

During handling of the above exception, another exception occurred:

Traceback (most recent call last):
  File "D:\Coding\Python\Tasks\venv\bin\Jobs.py", line 112, in enable_task
    jobs = self.server.enable_job(task_name)
  File "C:\Users\EYOYAYO\AppData\Local\Programs\Python\Python36\lib\site-packages\jenkins\__init__.py", line 1094, in enable_job
    'POST', self._build_url(ENABLE_JOB, locals())
  File "C:\Users\EYOYAYO\AppData\Local\Programs\Python\Python36\lib\site-packages\jenkins\__init__.py", line 541, in jenkins_open
    return self.jenkins_request(req, add_crumb, resolve_auth).text
  File "C:\Users\EYOYAYO\AppData\Local\Programs\Python\Python36\lib\site-packages\jenkins\__init__.py", line 573, in jenkins_request
    raise NotFoundException('Requested item could not be found')
jenkins.NotFoundException: Requested item could not be found
2018-08-12 21:27:44,642 - normal - INFO - <Response 84 bytes [200 OK]>
2018-08-12 22:48:20,830 - normal - ERROR - Requested item could not be found
Traceback (most recent call last):
  File "C:\Users\EYOYAYO\AppData\Local\Programs\Python\Python36\lib\site-packages\jenkins\__init__.py", line 560, in jenkins_request
    self._request(req))
  File "C:\Users\EYOYAYO\AppData\Local\Programs\Python\Python36\lib\site-packages\jenkins\__init__.py", line 511, in _response_handler
    response.raise_for_status()
  File "C:\Users\EYOYAYO\AppData\Local\Programs\Python\Python36\lib\site-packages\requests\models.py", line 939, in raise_for_status
    raise HTTPError(http_error_msg, response=self)
requests.exceptions.HTTPError: 404 Client Error: Not Found for url: http://localhost:8080/job/tasks/enable

During handling of the above exception, another exception occurred:

Traceback (most recent call last):
  File "D:\Coding\Python\Tasks\venv\bin\Jobs.py", line 115, in enable_task
    jobs = self.server.enable_job(task_name)
  File "C:\Users\EYOYAYO\AppData\Local\Programs\Python\Python36\lib\site-packages\jenkins\__init__.py", line 1094, in enable_job
    'POST', self._build_url(ENABLE_JOB, locals())
  File "C:\Users\EYOYAYO\AppData\Local\Programs\Python\Python36\lib\site-packages\jenkins\__init__.py", line 541, in jenkins_open
    return self.jenkins_request(req, add_crumb, resolve_auth).text
  File "C:\Users\EYOYAYO\AppData\Local\Programs\Python\Python36\lib\site-packages\jenkins\__init__.py", line 573, in jenkins_request
    raise NotFoundException('Requested item could not be found')
jenkins.NotFoundException: Requested item could not be found
2018-08-12 22:50:06,876 - normal - ERROR - Requested item could not be found
Traceback (most recent call last):
  File "C:\Users\EYOYAYO\AppData\Local\Programs\Python\Python36\lib\site-packages\jenkins\__init__.py", line 560, in jenkins_request
    self._request(req))
  File "C:\Users\EYOYAYO\AppData\Local\Programs\Python\Python36\lib\site-packages\jenkins\__init__.py", line 511, in _response_handler
    response.raise_for_status()
  File "C:\Users\EYOYAYO\AppData\Local\Programs\Python\Python36\lib\site-packages\requests\models.py", line 939, in raise_for_status
    raise HTTPError(http_error_msg, response=self)
requests.exceptions.HTTPError: 404 Client Error: Not Found for url: http://localhost:8080/job/tasks/enable

During handling of the above exception, another exception occurred:

Traceback (most recent call last):
  File "D:\Coding\Python\Tasks\venv\bin\Jobs.py", line 115, in enable_task
    jobs = self.server.enable_job(task_name)
  File "C:\Users\EYOYAYO\AppData\Local\Programs\Python\Python36\lib\site-packages\jenkins\__init__.py", line 1094, in enable_job
    'POST', self._build_url(ENABLE_JOB, locals())
  File "C:\Users\EYOYAYO\AppData\Local\Programs\Python\Python36\lib\site-packages\jenkins\__init__.py", line 541, in jenkins_open
    return self.jenkins_request(req, add_crumb, resolve_auth).text
  File "C:\Users\EYOYAYO\AppData\Local\Programs\Python\Python36\lib\site-packages\jenkins\__init__.py", line 573, in jenkins_request
    raise NotFoundException('Requested item could not be found')
jenkins.NotFoundException: Requested item could not be found
2018-08-12 22:50:06,879 - normal - INFO - <Response 84 bytes [200 OK]>
2018-08-12 22:50:16,417 - normal - INFO - <Response 58 bytes [200 OK]>
2018-08-13 17:37:38,183 - normal - INFO - null
2018-08-13 17:37:38,184 - normal - INFO - {'Task': 'Create the task', 'Job Name': 'tasks', 'Result': 'Successed', 'Error Code': '0', 'Description': 'Create the task tasks'}
2018-08-13 17:37:44,144 - normal - INFO - {"_class": "hudson.model.FreeStyleProject", "actions": [{}, {}, {}, {"_class": "com.cloudbees.plugins.credentials.ViewCredentialsAction"}], "buildable": true, "builds": [], "color": "notbuilt", "concurrentBuild": false, "description": null, "displayName": "tasks", "displayNameOrNull": null, "downstreamProjects": [], "firstBuild": null, "fullDisplayName": "tasks", "fullName": "tasks", "healthReport": [], "inQueue": false, "keepDependencies": false, "labelExpression": null, "lastBuild": null, "lastCompletedBuild": null, "lastFailedBuild": null, "lastStableBuild": null, "lastSuccessfulBuild": null, "lastUnstableBuild": null, "lastUnsuccessfulBuild": null, "name": "tasks", "nextBuildNumber": 1, "property": [], "queueItem": null, "scm": {"_class": "hudson.scm.NullSCM"}, "upstreamProjects": [], "url": "http://localhost:8080/job/tasks/"}
2018-08-13 17:37:44,145 - normal - INFO - {'Task': 'Get the task', 'Job Name': 'tasks', 'Result': 'Successed', 'Error Code': '0', 'Description': 'Get the tasks tasks'}
2018-08-13 17:37:55,543 - normal - INFO - null
2018-08-13 17:37:55,543 - normal - INFO - null
2018-08-13 17:38:12,875 - normal - INFO - {'Task': 'Build the task', 'Job Name': 'tasks', 'Result': 'Successed', 'Error Code': '0', 'Description': 'Get all the task tasks'}
2018-08-13 17:39:54,579 - normal - ERROR - Requested item could not be found
Traceback (most recent call last):
  File "C:\Users\EYOYAYO\AppData\Local\Programs\Python\Python36\lib\site-packages\jenkins\__init__.py", line 560, in jenkins_request
    self._request(req))
  File "C:\Users\EYOYAYO\AppData\Local\Programs\Python\Python36\lib\site-packages\jenkins\__init__.py", line 511, in _response_handler
    response.raise_for_status()
  File "C:\Users\EYOYAYO\AppData\Local\Programs\Python\Python36\lib\site-packages\requests\models.py", line 939, in raise_for_status
    raise HTTPError(http_error_msg, response=self)
requests.exceptions.HTTPError: 404 Client Error: Not Found for url: http://localhost:8080/job/tasks/doDelete

During handling of the above exception, another exception occurred:

Traceback (most recent call last):
  File "D:\Coding\Python\Tasks\venv\bin\Jobs.py", line 190, in delete_task
    jobs = self.server.delete_job(task_name)
  File "C:\Users\EYOYAYO\AppData\Local\Programs\Python\Python36\lib\site-packages\jenkins\__init__.py", line 1082, in delete_job
    'POST', self._build_url(DELETE_JOB, locals())
  File "C:\Users\EYOYAYO\AppData\Local\Programs\Python\Python36\lib\site-packages\jenkins\__init__.py", line 541, in jenkins_open
    return self.jenkins_request(req, add_crumb, resolve_auth).text
  File "C:\Users\EYOYAYO\AppData\Local\Programs\Python\Python36\lib\site-packages\jenkins\__init__.py", line 573, in jenkins_request
    raise NotFoundException('Requested item could not be found')
jenkins.NotFoundException: Requested item could not be found
2018-08-13 17:39:54,596 - normal - INFO - {'Task': 'Enable the task', 'Job Name': 'tasks', 'Result': 'Failed', 'Error Code': '404', 'Description': 'Requested item could not be found'}
2018-08-13 17:40:49,891 - normal - INFO - null
2018-08-13 17:40:49,892 - normal - INFO - {'Task': 'Create the task', 'Job Name': 'tasks', 'Result': 'Successed', 'Error Code': '0', 'Description': 'Create the task tasks'}
2018-08-13 17:40:54,765 - normal - INFO - null
2018-08-13 17:40:54,765 - normal - INFO - {'Task': 'Delete the task', 'Job Name': 'tasks', 'Result': 'Successed', 'Error Code': '0', 'Description': 'Get all the task tasks'}
